Workbook
Name MOTORISTAS: '[1]BANCO DE DADOS'!$B$2:$B$126
Name MOTORISTAS: '[2]BANCO DE DADOS'!$B$2:$B$126
Name MOTORISTAS: 'BANCO DE DADOS'!$B$2:$B$237

Sheet TEL. MADER
A1: Motorista | B1: Placa | C1: Telefone
A2: ADEVANIO | C2: (34) 9 9168-8833
A3: ALTAIR | B3: HJZ-2920 | C3: (34) 9 9118-4242
A4: ANDRÉ L. | B4: GWI-9577 | C4: (34) 9 9186-0201
A5: ANDRÉ D | B5: HHI-5839 | C5: (34) 9 9159-1001
A6: ANTONIO | B6: HOA-0784 | C6: (34) 9 9232-5790
A7: ARNALDO | C7: (34) 9 9903-9480
A8: BRUNO | B8: HIJ-5221 | C8: (34) 9 9288-0189
A9: BRUNO S. | B9: HHI-5840 | C9: (34) 9 9190-4446
A10: CASSIO | B10: OOY-7533 | C10: (34) 9 9198-7698
A11: CASSIANO | C11: (34) 9 9212-8632
A12: CLARICINDO | B12: HEU-1513 | C12: (34) 9 9256-7176
A13: CLÉRIO | B13: GWI-9546 | C13: (34) 9 9121-1943
A14: CRISTIANO | B14: HHI-5836 | C14: (34) 9 9301-0042
A15: DANIEL | C15: (34) 9 9216-0161
A16: DANILO | B16: HIJ-5226 | C16: (34) 9 9175-8193
A17: DENILSON | B17: GVE-7080 | C17: (34) 9 8402-4418
A18: EDI | C18: (34) 9 9175-8190
A19: EDINEOR | B19: HJW-4471 | C19: (34) 9 9152-0629
A20: EDILSON | C20: (34) 9 9222-7758
A21: EDSON (JESUS) | B21: HBG-1803 | C21: (34) 9 9242-6453
A22: EDUARDO | B22: OOY-7524 | C22: (34) 9 9271-1118
A23: EDUARDO B | C23: (34) 9 8824-2354
A24: EDVALDO | B24: OPT-3302 | C24: (34) 9 9234-4734
A25: EVALDO | C25: (34) 9 9161-5683
A26: FÁBIO | B26: OPT-3328 | C26: (34) 9 9300-1819
A27: FERNANDO | B27: GWI-9926 | C27: (34) 9 9986-0507
A28: FLAVIO P. | B28: HIJ-5296 | C28: (34) 9 9133-9990
A29: GLAYDSON | B29: HIJ-5039 | C29: (34) 9 9132-2991
A30: GUILHERME | C30: (34) 9 9143-2694
A31: HERMENEGILDO | B31: OOY-7530 | C31: (34) 9 9118-4242
A32: IGOR | C32: (34) 9 9144-5373
A33: ITALO | C33: (34) 9 9210-5908
A34: J. EDUARDO | B34: DVS-8940 | C34: (34) 9 9804-4994
A35: J.CARLOS | B35: HBN-0604 | C35: (34) 9 9277-7909
A36: JADSON | C36: (34) 9 9115-7136
A37: JAERTO | C37: (34) 9 9216-0157
A38: JESUS | B38: HBG-1803 | C38: (34) 9 9199-6958
A39: JOAO VARGAS | B39: HJZ-2926 | C39: (34) 9 9206-3531
A40: JOSE ROBERTO | C40: (37) 9 9115-2806
...

Sheet TEL. VC CARGAS
A1: OPERAÇÃO ZEMA
B2: OPERAÇÃO | C2: ZEMA
A3: FROTA | B3: Motorista | C3: Placa | D3: Telefone | E3: VIVO
A4: 370 | B4: Mateus | C4: CSK-6109 | D4: 9246-6679 | E4: 9984-0190
A5: 1040 | B5: Selio | C5: HHI-5833 | D5: 8810-5253 | E5: 9922-9502
A6: 1050 | B6: Julio | C6: HHI-5834 | D6: 9259-5180 | E6: 9919-5498
A7: 1060 | B7: Fernando Al. | C7: HHI-5835 | D7: 8899-6065 | E7: 9909-5962
A8: 1070 | B8: Adriano | C8: HHI-5837 | D8: 9157-6689 | E8: 9841-7639
A9: 1080 | B9: Cleiton | C9: HHI-5838 | D9: 8885-3134 | E9: 9838-4588
A10: 1090 | B10: Diego | C10: OLO-7407 | D10: 8869-9439 | E10: 9835-8925
A11: 1100 | B11: Otávio | C11: OLO-7431 | D11: 8820-1040 | E11: 9832-0955
A12: 1110 | B12: Leonardo | C12: OLO-7446 | D12: 35.9136-4696 | E12: 9981-0854
A13: 1120 | B13: Flávio | C13: OLO-7457 | D13: 9195-5184
A14: 1130 | B14: Fernando Ap | C14: OLO-7986 | D14: 9206-6957 | E14: 9935-6902
A15: 1140 | B15: Fredson | C15: OLO-8004 | D15: 8853-2816 | E15: 9814-1519
A16: 1150 | B16: Cristiano | C16: OLO-8015 | D16: 8871-4624 | E16: 9946-9287
A17: 1160 | B17: Marcio Z. | C17: PUG-8722 | D17: 9910-2827 | E17: 9808-9374
A18: 1170 | B18: Belchior | C18: PUG-8680 | D18: 9950-8953 | E18: 9804-7646
A19: 1180 | B19: Marciano | C19: PUG-8711 | D19: 8834-8654 | E19: 9802-6714
A20: 1190 | B20: Juliano | C20: PUG-8745 | D20: 9321-5363 | E20: 9800-9410
A21: 1200 | B21: Devanir | C21: PUG-8717 | D21: 9233-9484 | E21: 9988-3868
A22: 1210 | B22: Jaime | C22: PUG-8700 | D22: 9177-6507 | E22: 9987-7674
A23: 1220 | B23: Junio | C23: PUG-8701 | D23: 8830-5681 | E23: 9923-5604
A24: 1230 | B24: Alexandre | C24: PUG-8728 | D24: 9232-4986 | E24: 9822-8535
A25: 1240 | B25: Baltazar | C25: PUG-8689 | D25: 9230-7861 | E25: 9932-2690
... A30: 500 | B30: Claudio | C30: HIJ-5288 | D30: 9146-4069 | E30: 9819-9270
A31: 940 | C31: PUG-4401
A32: 950 | B32: Donizete | C32: PUG-8650 | D32: 9804-8156 | E32: 9959-4015
A33: 960 | C33: PUG-4394
A34: 970 | C34: PUG-4407
A35: 990 | C35: PUG-8658
A36: 750 | B36: Edcarlos | C36: OPS-1275 | D36: 9637-1059 | E36: 9166-1725
A37: 1010 | C37: PUG-4388
A38: 1020 | C38: PUG-4411
B41: ALINE | E41: 9800-2878
B42: FLÁVIO | E42: 9838-9005
A44: FÉRIAS | B44: Alex Sandro | C44: OLO-7431 | D44: 9129-9665 | E44: 9826-6787

Sheet TEL OUTROS
B2: MOTORISTA | C2: PLACA | D2: TRANSPORTADORA | E2: TELEFONE
B3: Frederico | D3: Acorinte | E3: (35) 9 9209-9790
B4: Valmir | D4: Acorinte | E4: (35) 9 9836-2588
B5: Leonardo | C5: BUP-1415 | D5: Acorinte | E5: (35) 9 9737-0473
B6: Daniel | C6: BYF-8649 | D6: Acorinte | E6: (35) 9 9117-2194
B7: Rodrigo | C7: KBU-5630 | D7: Acorinte | E7: (35) 9 9172-4311
B8: Antonio | C8: GMT-1689 | D8: Acorinte | E8: (35) 9 9194-8386
B9: Ademar | C9: GZE-5084 | D9: J.I.M. | E9: (34) 9 8828-1300
B10: Roberto | C10: GZE-5084 | D10: J.I.M. | E10: (34) 9 9118-4713 | F10: (34) 9 9318-8057
B11: Eduardo | C11: DBC-9862 | D11: Norton | E11: (34) 9 8824-2354
B12: Ivan | C12: IKF-3236 | D12: J.I.M. | E12: (34) 9 9159-3639
B13: Renato | C13: GPD-0598 | D13: Rodoágil | E13: (34) 9 9834-4030
B14: Gleison | C14: JVO-5119 | D14: Rodoágil | E14: (34) 9 9290-7557
B15: Pedro | C15: 3661-7478 | D15: Rodoágil | E15: (34) 9 9981-2134
B16: Vinícius | D16: Rodoágil | E16: (34) 9 9290-7473
B17: Luis Andre | D17: Rodoágil | E17: (34) 9 9107-3968
B18: Dionatan | C18: - | D18: Rodoágil | E18: (34) 9 9290-7654
B19: Janielison | D19: Rodoágil | E19: (34) 9 8820-0054
B20: Sebastião | C20: BYB-7814 | D20: S Ferreira | E20: (35) 9 9185-0377 | F20: 9 9942-1680
B21: Guilherme | C21: GYI-1002 | D21: S Ferreira | E21: (35) 9 9215-5387
B22: Edmar | C22: AFE-2202 | D22: TransMale | E22: (34) 98844-4551
B23: Daniel | C23: DBJ-9185 | D23: TransMale | E23: (34) 9 9127-3655
B24: Emerson | C24: HJI-3049 | D24: TransMale | E24: (34) 9 9947-3782
B25: João Mota | C25: GKF-0309 | D25: TransMale | E25: (38) 9 8811-9673
B26: Jose Pedro | C26: GKO-5438 | D26: TransMale | E26: (34) 9 9155-9326
B27: Valter | C27: OPT-3321 | D27: V & M | E27: (34) 9 9905-8578

Sheet MODELO
D1: FORNECEDOR | E1: CEP
D2: COLORMAQ | E2: 16026340
D3: COLORMAQ (CONTAGEM) | E3: 16026340
D4: COLORMAQ (SERRA ES) | E4: 16026340
D5: SUGGAR | E5: 30390150
D6: MOTOBRAS | E6: 37530000
D7: MOTOBRAS/WALITA | E7: 37530000
D8: GRIFIT LAVADORAS | E8: 37545000
D9: ZEMA MODA CAPETINGA | E9: 37993000
D10: AMAPA(ARMARIOS) - USO E CONSUMO | E10: 35530000
D11: MONDIAL | E11: 44245000
D12: PAPEL A4 - USO E CONSUMO | E12: 32044350
D13: PANASONIC | E13: 37655000
... D38: CARREGAMENTO SERRA | E38: 29161389

Sheet BANCO DE DADOS
B1: MOTORISTA | C1: TRANSPORTADORA | D1: TELEFONE
B2: ADEVANIO (MADER) | C2: MADER | D2: (34) 9 9168-8833 | G2: OPERAÇÃO | H2: ZEMA
B3: PAULO HENRIQUE (MADER) | C3: MADER | D3: (34) 9 9142-7902
B4: ALEMAR (VC) | C4: MADER | D4: (34) 9 9241-1119
B5: ADILSON ADRIANO(MADER) | C5: MADER | D5: (34) 9 9925-0487 | F5: FROTA | G5: Motorista | H5: Placa | I5: Telefone | J5: VIVO | L5: RENAVAM
B6: ANTERO DE LIMA(MADER) | C6: MADER | D6: (34) 9 9840-9159
B7: ALTAIR (MADER) | C7: MADER | D7: (34) 3661-7358 | F7: 370 | G7: Mateus | H7: CSK-6109 | I7: 9246-6679 | J7: 9984-0190 | L7: 163007730
B8: AMIR (MADER) | C8: MADER | D8: (34) 98838-7695 | F8: 1040 | G8: Selio | H8: HHI-5833 | I8: 8810-5253 | J8: 9922-9502 | L8: 00330284274 | M8: Razão Social: Cidade das Aguas Transporte Eireli
B9: ANDRÉ L. (MADER) | C9: MADER | D9: (34) 9 9174-3586 | F9: 1060 | G9: Fernando Al. | H9: HHI-5835 | I9: 8899-6065 | J9: 9909-5962 | L9: 00330286013 | M9: IE: 040.939282.00-22
B10: ANTONIO (MADER) | C10: MADER | D10: (34) 9 9232-5790 | F10: 1070 | G10: Adriano | H10: HHI-5837 | I10: 9157-6689 | J10: 9841-7639 | L10: 00330232720 | M10: Endereço: R. Dom José Gaspar, 675
B11: ANTONIO CARLOS (MADER) | C11: MADER | D11: (34) 3661-7358 | F11: 1080 | G11: Otávio | H11: HHI-5838 | I11: 8820-1040 | J11: 9832-0955 | L11: 00330233823 | M11: Bairro: Centro
B12: ARNALDO (MADER) | C12: MADER | D12: (34) 9 9903-9480 | F12: 1090 | G12: Diego | H12: OLO-7407 | I12: 8869-9439 | J12: 9835-8925 | L12: 00470309172 | M12: Araxá-MG Cep: 38.183-188
B13: BRUNO FARIA (MADER) | C13: MADER | D13: (34) 9 9215-8397 | F13: 1100 | G13: Alex Sandro | H13: OLO-7431 | I13: 9129-9665 | J13: 9826-6787 | L13: 00470309520 | M13: Cep: 38.183-188
B14: BRUNO (MADER) | C14: MADER | D14: (34) 9 9302-7775 | F14: 1110 | G14: Leonardo | H14: OLO-7446 | I14: 35.9136-4696 | J14: 9981-0854 | K14: (34) 9 99840190 | L14: 00470310855 | M14: Telefone: (34) 3669.2500
B15: BRENO QUIRINO(MADER) | C15: MADER | D15: (34) 9 9937-0928 | F15: 1120 | G15: Flávio | H15: OLO-7457 | I15: 9195-5184 | L15: 00470307943
B16: CASSIO (MADER) | C16: MADER | D16: (34) 9 9198-7698
B17: CASSIANO (MADER) | C17: MADER | D17: (34) 9 9212-8632 | F17: 1130 | G17: Fernando Ap | H17: OLO-7986 | I17: 9206-6957 | J17: 9935-6902 | L17: 00470308575
B18: CELIO ADRIANO (MADER) | C18: MADER | D18: (37) 9 9121-8420 | F18: 1140 | G18: Fredson | H18: OLO-8004 | I18: 8853-2816 | J18: 9814-1519 | L18: 00470306742
B19: CLAUDIO (MADER) | C19: MADER | D19: (34) 9 9667-2308 | F19: 1150 | G19: Cristiano | H19: OLO-8015 | I19: 8871-4624 | J19: 9946-9287 | L19: 00470307269
B20: CARLOS EDUARDO(MADER) | C20: MADER | D20: (31) 9 8238-3996 | F20: 1160 | G20: Marcio Z. | H20: PUG-8722 | I20: 9910-2827 | J20: 9808-9374 | L20: 01013993800
B21: CLERIO (MADER) | C21: MADER | D21: (34) 9 9271-1122 | F21: 1170 | G21: Belchior | H21: PUG-8680 | I21: 9950-8953 | J21: 9804-7646 | L21: 1013995993
B22: CRISTIANO (MADER) | C22: MADER | D22: (34) 9 9301-0042 | F22: 1180 | G22: Marciano | H22: PUG-8711 | I22: 8834-8654 | J22: 9802-6714 | L22: 1014000260
B23: DANIEL (MADER) | C23: MADER | D23: (34) 9 9109-1318
B24: DANILO (MADER) | C24: MADER | D24: (34) 9 8841-9278
B25: DENILSON (MADER) | C25: MADER | D25: (34) 9 8402-4418 | F25: 1190 | G25: Juliano | H25: PUG-8745 | I25: 9321-5363 | J25: 9800-9410 | L25: 01013998240
B26: GEOGENES (MADER) | C26: MADER | D26: (34) 9 8827-7820 | F26: 1200 | G26: Devanir | H26: PUG-8717 | I26: 9233-9484 | J26: 9988-3868 | L26: 1013988962
B27: DRUMONT (MADER) | C27: MADER | D27: (34) 9 8849-5822 | F27: 1210 | G27: Jaime | H27: PUG-8700 | I27: 9177-6507 | J27: 9987-7674 | L27: 01013994628
B28: EDI (MADER) | C28: MADER | D28: (34) 9 9175-8190 | F28: 1220 | G28: Junio | H28: PUG-8701 | I28: 8830-5681 | J28: 9923-5604 | L28: 1013988407
B29: EDINEOR (MADER) | C29: MADER | D29: (34) 9 9152-0629 | F29: 1230 | G29: Paulo | H29: PUG-8728 | I29: 9241-7671 | J29: 9930-7308 | L29: 01013996817
B30: EDILSON (MADER) | C30: MADER | D30: (34) 9 9222-7758 | F30: 1240 | G30: Baltazar | H30: PUG-8689 | I30: 9230-7861 | J30: 9932-2690 | L30: 1013987583
B31: EDSON (MADER) | C31: MADER | D31: (34) 9 9242-6453
B32: EDUARDO (MADER) | C32: MADER | D32: (34) 9 9271-1118
B33: EDUARDO C (MADER) | C33: MADER | D33: (34) 9 9265-5803 | F33: 1250 | G33: Rodrigo L. | H33: PUG-8688 | I33: 8809-2135 | J33: 9935-1228 | L33: 1013990754
B34: EURIPEDES (MADER) | C34: MADER | D34: (34) 9 9946-9520 | F34: 1260 | G34: Neuber | H34: PUG-8730 | I34: 8809-2135 | J34: 9948-8637 | L34: 01014007140
B35: EDER (MADER) | C35: MADER | D35: (34) 9 8820-0870 | F35: 1270 | G35: Rodrigo S. | H35: PUG-8683 | I35: 8803-4013 | J35: 9943-3455 | L35: 1013991998
B36: EDVALDO (MADER) | C36: MADER | D36: (34) 9 9234-4734 | F36: 480 | G36: Bruno R. | H36: HIJ-5268 | I36: 9840-3238 | J36: 9983-8424
B37: ELIEL(MADER) | C37: MADER | D37: (34) 9 9806 -7072 | F37: 500 | G37: Alexandre | H37: HIJ-5288 | I37: 9232-4986 | J37: 9822-8535
B38: FABIO (MADER) | C38: MADER | D38: (34) 9 9956-6248
B39: FERNANDO (V&M) | C39: V&M | D39: (34) 9 2000-8517 | F39: 940 | H39: PUG-4401
B40: FLAVIO P (MADER) | C40: MADER | D40: (34) 9 9133-9990
...

Sheet IMPRESSÃO
B2: PROGRAMAÇÃO DE DESCARGA NA FILIAL | G2: PROGRAMAÇÃO DE DESCARGA NA FILIAL | L2: PROGRAMAÇÃO DE DESCARGA NA FILIAL | Q2: PROGRAMAÇÃO DE DESCARGA NA FILIAL
B28: PROGRAMAÇÃO DE DESCARGA NA FILIAL | G28: PROGRAMAÇÃO DE DESCARGA NA FILIAL | L28: PROGRAMAÇÃO DE DESCARGA NA FILIAL | Q28: PROGRAMAÇÃO DE DESCARGA NA FILIAL
B54: PROGRAMAÇÃO DE DESCARGA NA FILIAL | G54: PROGRAMAÇÃO DE DESCARGA NA FILIAL | L54: PROGRAMAÇÃO DE DESCARGA NA FILIAL | Q54: PROGRAMAÇÃO DE DESCARGA NA FILIAL
B80: PROGRAMAÇÃO DE DESCARGA NA FILIAL | G80: PROGRAMAÇÃO DE DESCARGA NA FILIAL | L80: PROGRAMAÇÃO DE DESCARGA NA FILIAL | Q80: PROGRAMAÇÃO DE DESCARGA NA FILIAL
B106: PROGRAMAÇÃO DE DESCARGA NA FILIAL | G106: PROGRAMAÇÃO DE DESCARGA NA FILIAL | L106: PROGRAMAÇÃO DE DESCARGA NA FILIAL | Q106: PROGRAMAÇÃO DE DESCARGA NA FILIAL
B132: PROGRAMAÇÃO DE DESCARGA NA FILIAL | G132: PROGRAMAÇÃO DE DESCARGA NA FILIAL | L132: PROGRAMAÇÃO DE DESCARGA NA FILIAL | Q132: PROGRAMAÇÃO DE DESCARGA NA FILIAL
B158: PROGRAMAÇÃO DE DESCARGA NA FILIAL | G158: PROGRAMAÇÃO DE DESCARGA NA FILIAL | L158: PROGRAMAÇÃO DE DESCARGA NA FILIAL | Q158: PROGRAMAÇÃO DE DESCARGA NA FILIAL
B184: PROGRAMAÇÃO DE DESCARGA NA FILIAL | G184: PROGRAMAÇÃO DE DESCARGA NA FILIAL | L184: PROGRAMAÇÃO DE DESCARGA NA FILIAL | Q184: PROGRAMAÇÃO DE DESCARGA NA FILIAL
B210: PROGRAMAÇÃO DE DESCARGA NA FILIAL | G210: PROGRAMAÇÃO DE DESCARGA NA FILIAL | L210: PROGRAMAÇÃO DE DESCARGA NA FILIAL | Q210: PROGRAMAÇÃO DE DESCARGA NA FILIAL
B236: PROGRAMAÇÃO DE DESCARGA NA FILIAL | G236: PROGRAMAÇÃO DE DESCARGA NA FILIAL | L236: PROGRAMAÇÃO DE DESCARGA NA FILIAL | Q236: PROGRAMAÇÃO DE DESCARGA NA FILIAL
B262: PROGRAMAÇÃO DE DESCARGA NA FILIAL | G262: PROGRAMAÇÃO DE DESCARGA NA FILIAL | L262: PROGRAMAÇÃO DE DESCARGA NA FILIAL | Q262: PROGRAMAÇÃO DE DESCARGA NA FILIAL
B288: PROGRAMAÇÃO DE DESCARGA NA FILIAL | G288: PROGRAMAÇÃO DE DESCARGA NA FILIAL | L288: PROGRAMAÇÃO DE DESCARGA NA FILIAL | Q288: PROGRAMAÇÃO DE DESCARGA NA FILIAL
... B340: PROGRAMAÇÃO DE DESCARGA NA FILIAL | G340: PROGRAMAÇÃO DE DESCARGA NA FILIAL | L340: PROGRAMAÇÃO DE DESCARGA NA FILIAL | Q340: PROGRAMAÇÃO DE DESCARGA NA FILIAL

Sheet IMPRESSÃO-CAPA
B2: SR MOTORISTA, FAVOR CONFERIR DOCUMENTAÇÃO, NOTAS FISCAIS, PASTA E MALOTES. SEGUE ABAIXO A ORDEM DE DESCARGA. | G2: SR MOTORISTA, FAVOR CONFERIR DOCUMENTAÇÃO, NOTAS FISCAIS, PASTA E MALOTES. SEGUE ABAIXO A ORDEM DE DESCARGA. | L2: SR MOTORISTA, FAVOR CONFERIR DOCUMENTAÇÃO, NOTAS FISCAIS, PASTA E MALOTES. SEGUE ABAIXO A ORDEM DE DESCARGA. | R2: SR MOTORISTA, FAVOR CONFERIR DOCUMENTAÇÃO, NOTAS FISCAIS, PASTA E MALOTES. SEGUE ABAIXO A ORDEM DE DESCARGA.
B9: 1 | C9: =C25 -> CARANGOLA - 234 | G9: 1 | H9: =H25 -> PADRE PARAISO - 139 | L9: 1 | M9: =M25 -> UNAI - 56 | R9: 1 | S9: =S25 -> 0
B10: =B9+1 -> 2 | C10: =C26 -> ALMOÇO | G10: =G9+1 -> 2 | H10: =H26 -> ITAIPE - 453 | L10: =L9+1 -> 2 | M10: =M26 -> BURITIS - 122 | R10: =R9+1 -> 2 | S10: =S26 -> 0
B11: =B10+1 -> 3 | C11: =C27 -> AFONSO CLAUDIO - 331 | G11: =G10+1 -> 3 | H11: =H27 -> NOVO CRUZEIRO - 137 | R11: =R10+1 -> 3 | S11: =S27 -> 0
B12: =B11+1 -> 4 | C12: =C28 -> CASTELO - 448 | R12: =R11+1 -> 4 | S12: =S28 -> 0
B13: =B12+1 -> 5 | C13: =C29 -> ANCHIETA - 441 | R13: =R12+1 -> 5 | S13: =S29 -> 0
B14: =B13+1 -> 6 | C14: =C30 -> MARATAIZES - 424 | R14: =R13+1 -> 6 | S14: =S30 -> 0
B15: =B14+1 -> 7 | C15: =C31 -> ITAPEMIRIM - 392 | R15: =R14+1 -> 7 | S15: =S31 -> 0
B16: =B15+1 -> 8 | C16: =C32 -> CARREGAMENTO | R16: =R15+1 -> 8 | S16: =S32 -> 0
R17: =R16+1 -> 9 | S17: =S33 -> 0
R18: =R17+1 -> 10 | S18: =S34 -> 0
R19: =R18+1 -> 11 | S19: =S35 -> 0
B22: PROGRAMAÇÃO DE DESCARGA NA FILIAL | G22: PROGRAMAÇÃO DE DESCARGA NA FILIAL | L22: PROGRAMAÇÃO DE DESCARGA NA FILIAL | R22: PROGRAMAÇÃO DE DESCARGA NA FILIAL
B23: ROTA LARANJA A 01 | C23: OSVALDO (MADER) | D23: OOY-7533 | G23: ROTA LARANJA A 11 | H23: PAULO S (M&S) | I23: PWL-3094 | L23: ROTA EXTRA 10 | M23: DRUMONT (MADER) | N23: HHI-5832
B25: 45698 | C25: CARANGOLA - 234 | D25: 0.33333333 | G25: 45698 | H25: PADRE PARAISO - 139 | I25: 0.33333333 | L25: 45698 | M25: UNAI - 56 | N25: 0.25
B26: 45698 | C26: ALMOÇO | D26: 12:30/13:30 | G26: 45698 | H26: ITAIPE - 453 | I26: 0.4375 | L26: 45698 | M26: BURITIS - 122 | N26: 0.45833333
B27: 45698 | C27: AFONSO CLAUDIO - 331 | D27: 0.5625 | G27: 45698 | H27: NOVO CRUZEIRO - 137 | I27: 0.54166667
B28: 45698 | C28: CASTELO - 448 | D28: 0.6875
B29: 45699 | C29: ANCHIETA - 441 | D29: 0.33333333
B30: 45699 | C30: MARATAIZES - 424 | D30: 0.45833333
B31: 45699 | C31: ITAPEMIRIM - 392 | D31: 0.58333333
B32: 45700 | C32: CARREGAMENTO | D32: RUFATO
B34: TEL DO MOTORISTA | D34: =VLOOKUP(C23,'BANCO DE DADOS'!$B$2:$D$260,3,FALSE) -> (34) 9 9175-8193 | G34: TEL DO MOTORISTA | I34: =VLOOKUP(H23,'BANCO DE DADOS'!$B$2:$D$260,3,FALSE) -> (34) 9 9241-7671 | L34: TEL DO MOTORISTA | N34: =VLOOKUP(M23,'BANCO DE DADOS'!$B$2:$D$260,3,FALSE) -> (34) 9 8849-5822
B47: SR MOTORISTA, FAVOR CONFERIR DOCUMENTAÇÃO, NOTAS FISCAIS, PASTA E MALOTES. SEGUE ABAIXO A ORDEM DE DESCARGA. | G47: SR MOTORISTA, FAVOR CONFERIR DOCUMENTAÇÃO, NOTAS FISCAIS, PASTA E MALOTES. SEGUE ABAIXO A ORDEM DE DESCARGA. | L47: SR MOTORISTA, FAVOR CONFERIR DOCUMENTAÇÃO, NOTAS FISCAIS, PASTA E MALOTES. SEGUE ABAIXO A ORDEM DE DESCARGA. | R47: SR MOTORISTA, FAVOR CONFERIR DOCUMENTAÇÃO, NOTAS FISCAIS, PASTA E MALOTES. SEGUE ABAIXO A ORDEM DE DESCARGA.
B54: 1 | C54: =C70 -> MATIPO - 214 | G54: 1 | H54: =H70 -> TEOFILO OTONI - 289 | L54: 1 | M54: =M70 -> LADAINHA - 549 | R54: 1 | S54: ARAXÁ - 04
B55: =B54+1 -> 2 | C55: =C71 -> ABRE CAMPO - 335 | G55: =G54+1 -> 2 | H55: =H71 -> CARREGAMENTO | L55: =L54+1 -> 2 | M55: =M71 -> CARAÍ - 550 | R55: =R54+1 -> 2 | S55: TAPIRA - 603
B56: =B55+1 -> 3 | C56: =C72 -> SANTA MARGARIDA - 433
B57: =B56+1 -> 4 | C57: =C73 -> ALMOÇO
B58: =B57+1 -> 5 | C58: =C74 -> IPANEMA - 282
B59: =B58+1 -> 6 | C59: =C75 -> MANHUMIRIM - 232
B60: =B59+1 -> 7 | C60: =C76 -> ESPERA FELIZ - 212
B61: =B60+1 -> 8 | C61: =C77 -> DIVINO - 310
B62: =B61+1 -> 9 | C62: =C78 -> CARREGAMENTO
B67: PROGRAMAÇÃO DE DESCARGA NA FILIAL | G67: PROGRAMAÇÃO DE DESCARGA NA FILIAL | L67: PROGRAMAÇÃO DE DESCARGA NA FILIAL | R67: PROGRAMAÇÃO DE DESCARGA NA FILIAL
B68: ROTA LARANJA A 02 | C68: RODRIGO (MADER) | D68: HJZ-2926 | G68: ROTA EXTRA 01 | H68: JOAO HENRIQUE (MADER) | I68: HHI-5836 | L68: INAUGURAÇÃO | M68: GEOMAR (VC) | N68: PUG-8717
B70: 45698 | C70: MATIPO - 214 | D70: 0.33333333 | G70: 45698 | H70: TEOFILO OTONI - 289 | I70: 0.29166667 | L70: 45698 | M70: LADAINHA - 549 | N70: 0.33333333
B71: 45698 | C71: ABRE CAMPO - 335 | D71: 0.41666667 | G71: 45699 | H71: CARREGAMENTO | I71: PLASTICO BOLHA | L71: 45698 | M71: CARAÍ - 550 | N71: 0.58333333
B72: 45698 | C72: SANTA MARGARIDA - 433 | D72: 0.5
B73: 45698 | C73: ALMOÇO | D73: 14:00/15:00
B74: 45698 | C74: IPANEMA - 282 | D74: 0.64583333
...
